2022-01-31 19:26:17,367 ERROR: Exception on / [GET] [in /Users/rossroberts/repositories/MediaTracker/env/lib/python3.9/site-packages/flask/app.py:1457]
Traceback (most recent call last):
  File "/Users/rossroberts/repositories/MediaTracker/env/lib/python3.9/site-packages/flask/app.py", line 2073, in wsgi_app
    response = self.full_dispatch_request()
  File "/Users/rossroberts/repositories/MediaTracker/env/lib/python3.9/site-packages/flask/app.py", line 1518, in full_dispatch_request
    rv = self.handle_user_exception(e)
  File "/Users/rossroberts/repositories/MediaTracker/env/lib/python3.9/site-packages/flask/app.py", line 1516, in full_dispatch_request
    rv = self.dispatch_request()
  File "/Users/rossroberts/repositories/MediaTracker/env/lib/python3.9/site-packages/flask/app.py", line 1502, in dispatch_request
    return self.ensure_sync(self.view_functions[rule.endpoint])(**req.view_args)
  File "/Users/rossroberts/repositories/MediaTracker/env/lib/python3.9/site-packages/flask_login/utils.py", line 272, in decorated_view
    return func(*args, **kwargs)
  File "/Users/rossroberts/repositories/MediaTracker/app/routes.py", line 56, in index
    return render_template('index.html', title='Home Page', form=form, post=posts)
  File "/Users/rossroberts/repositories/MediaTracker/env/lib/python3.9/site-packages/flask/templating.py", line 147, in render_template
    return _render(
  File "/Users/rossroberts/repositories/MediaTracker/env/lib/python3.9/site-packages/flask/templating.py", line 128, in _render
    rv = template.render(context)
  File "/Users/rossroberts/repositories/MediaTracker/env/lib/python3.9/site-packages/jinja2/environment.py", line 1291, in render
    self.environment.handle_exception()
  File "/Users/rossroberts/repositories/MediaTracker/env/lib/python3.9/site-packages/jinja2/environment.py", line 925, in handle_exception
    raise rewrite_traceback_stack(source=source)
  File "/Users/rossroberts/repositories/MediaTracker/app/templates/index.html", line 1, in top-level template code
    {% extends "base.html" %}
  File "/Users/rossroberts/repositories/MediaTracker/app/templates/base.html", line 33, in top-level template code
    {% block content %}{% endblock %}
  File "/Users/rossroberts/repositories/MediaTracker/app/templates/index.html", line 24, in block 'content'
    {% for error in form.post.errors %}
  File "/Users/rossroberts/repositories/MediaTracker/env/lib/python3.9/site-packages/jinja2/environment.py", line 474, in getattr
    return getattr(obj, attribute)
jinja2.exceptions.UndefinedError: 'app.forms.AddMovieForm object' has no attribute 'post'
2022-01-31 19:27:43,001 INFO: MediaTracker Startup [in /Users/rossroberts/repositories/MediaTracker/app/__init__.py:47]
2022-01-31 19:28:25,084 ERROR: Exception on / [POST] [in /Users/rossroberts/repositories/MediaTracker/env/lib/python3.9/site-packages/flask/app.py:1457]
Traceback (most recent call last):
  File "/Users/rossroberts/repositories/MediaTracker/env/lib/python3.9/site-packages/sqlalchemy/engine/base.py", line 1802, in _execute_context
    self.dialect.do_execute(
  File "/Users/rossroberts/repositories/MediaTracker/env/lib/python3.9/site-packages/sqlalchemy/engine/default.py", line 732, in do_execute
    cursor.execute(statement, parameters)
sqlite3.InterfaceError: Error binding parameter 7 - probably unsupported type.

The above exception was the direct cause of the following exception:

Traceback (most recent call last):
  File "/Users/rossroberts/repositories/MediaTracker/env/lib/python3.9/site-packages/flask/app.py", line 2073, in wsgi_app
    response = self.full_dispatch_request()
  File "/Users/rossroberts/repositories/MediaTracker/env/lib/python3.9/site-packages/flask/app.py", line 1518, in full_dispatch_request
    rv = self.handle_user_exception(e)
  File "/Users/rossroberts/repositories/MediaTracker/env/lib/python3.9/site-packages/flask/app.py", line 1516, in full_dispatch_request
    rv = self.dispatch_request()
  File "/Users/rossroberts/repositories/MediaTracker/env/lib/python3.9/site-packages/flask/app.py", line 1502, in dispatch_request
    return self.ensure_sync(self.view_functions[rule.endpoint])(**req.view_args)
  File "/Users/rossroberts/repositories/MediaTracker/env/lib/python3.9/site-packages/flask_login/utils.py", line 272, in decorated_view
    return func(*args, **kwargs)
  File "/Users/rossroberts/repositories/MediaTracker/app/routes.py", line 29, in index
    db.session.commit()
  File "<string>", line 2, in commit
  File "/Users/rossroberts/repositories/MediaTracker/env/lib/python3.9/site-packages/sqlalchemy/orm/session.py", line 1431, in commit
    self._transaction.commit(_to_root=self.future)
  File "/Users/rossroberts/repositories/MediaTracker/env/lib/python3.9/site-packages/sqlalchemy/orm/session.py", line 829, in commit
    self._prepare_impl()
  File "/Users/rossroberts/repositories/MediaTracker/env/lib/python3.9/site-packages/sqlalchemy/orm/session.py", line 808, in _prepare_impl
    self.session.flush()
  File "/Users/rossroberts/repositories/MediaTracker/env/lib/python3.9/site-packages/sqlalchemy/orm/session.py", line 3363, in flush
    self._flush(objects)
  File "/Users/rossroberts/repositories/MediaTracker/env/lib/python3.9/site-packages/sqlalchemy/orm/session.py", line 3503, in _flush
    transaction.rollback(_capture_exception=True)
  File "/Users/rossroberts/repositories/MediaTracker/env/lib/python3.9/site-packages/sqlalchemy/util/langhelpers.py", line 70, in __exit__
    compat.raise_(
  File "/Users/rossroberts/repositories/MediaTracker/env/lib/python3.9/site-packages/sqlalchemy/util/compat.py", line 207, in raise_
    raise exception
  File "/Users/rossroberts/repositories/MediaTracker/env/lib/python3.9/site-packages/sqlalchemy/orm/session.py", line 3463, in _flush
    flush_context.execute()
  File "/Users/rossroberts/repositories/MediaTracker/env/lib/python3.9/site-packages/sqlalchemy/orm/unitofwork.py", line 456, in execute
    rec.execute(self)
  File "/Users/rossroberts/repositories/MediaTracker/env/lib/python3.9/site-packages/sqlalchemy/orm/unitofwork.py", line 630, in execute
    util.preloaded.orm_persistence.save_obj(
  File "/Users/rossroberts/repositories/MediaTracker/env/lib/python3.9/site-packages/sqlalchemy/orm/persistence.py", line 244, in save_obj
    _emit_insert_statements(
  File "/Users/rossroberts/repositories/MediaTracker/env/lib/python3.9/site-packages/sqlalchemy/orm/persistence.py", line 1221, in _emit_insert_statements
    result = connection._execute_20(
  File "/Users/rossroberts/repositories/MediaTracker/env/lib/python3.9/site-packages/sqlalchemy/engine/base.py", line 1614, in _execute_20
    return meth(self, args_10style, kwargs_10style, execution_options)
  File "/Users/rossroberts/repositories/MediaTracker/env/lib/python3.9/site-packages/sqlalchemy/sql/elements.py", line 325, in _execute_on_connection
    return connection._execute_clauseelement(
  File "/Users/rossroberts/repositories/MediaTracker/env/lib/python3.9/site-packages/sqlalchemy/engine/base.py", line 1481, in _execute_clauseelement
    ret = self._execute_context(
  File "/Users/rossroberts/repositories/MediaTracker/env/lib/python3.9/site-packages/sqlalchemy/engine/base.py", line 1845, in _execute_context
    self._handle_dbapi_exception(
  File "/Users/rossroberts/repositories/MediaTracker/env/lib/python3.9/site-packages/sqlalchemy/engine/base.py", line 2026, in _handle_dbapi_exception
    util.raise_(
  File "/Users/rossroberts/repositories/MediaTracker/env/lib/python3.9/site-packages/sqlalchemy/util/compat.py", line 207, in raise_
    raise exception
  File "/Users/rossroberts/repositories/MediaTracker/env/lib/python3.9/site-packages/sqlalchemy/engine/base.py", line 1802, in _execute_context
    self.dialect.do_execute(
  File "/Users/rossroberts/repositories/MediaTracker/env/lib/python3.9/site-packages/sqlalchemy/engine/default.py", line 732, in do_execute
    cursor.execute(statement, parameters)
sqlalchemy.exc.InterfaceError: (sqlite3.InterfaceError) Error binding parameter 7 - probably unsupported type.
[SQL: INSERT INTO screen (title, genre, year, watched, my_rating, rt_rating, watched_date, tags) VALUES (?, ?, ?, ?, ?, ?, ?, ?)]
[parameters: ('Boondock Saints', 'Action', 2002, 1, 75, 75, '2022-01-04', {'title': 'Boondock Saints', 'genre': 'Action', 'year': 2002, 'watched': True, 'my_rating': 75, 'rt_rating': 54, 'watched_date': datetime.date(2022, 1, 4), 'tags': '', 'submit': True, 'csrf_token': 'IjYwZTQ3OGRlZGFlY2VlYjM3NWQwMjdlZjQ4NDk1ODRmNmIxM2FjMGYi.Yfh-gQ.N9ZGy_sc3S7mIZTqHJBuNA-KNIw'})]
(Background on this error at: https://sqlalche.me/e/14/rvf5)
2022-02-01 08:29:47,040 INFO: MediaTracker Startup [in /Users/rossroberts/repositories/MediaTracker/app/__init__.py:47]
