2022-02-20 17:28:49,020 ERROR: Exception on /favicon.ico [GET] [in /Users/rossroberts/repositories/MediaTracker/env/lib/python3.9/site-packages/flask/app.py:1457]
Traceback (most recent call last):
  File "/Users/rossroberts/repositories/MediaTracker/env/lib/python3.9/site-packages/flask/app.py", line 1516, in full_dispatch_request
    rv = self.dispatch_request()
  File "/Users/rossroberts/repositories/MediaTracker/env/lib/python3.9/site-packages/flask/app.py", line 1492, in dispatch_request
    self.raise_routing_exception(req)
  File "/Users/rossroberts/repositories/MediaTracker/env/lib/python3.9/site-packages/flask/app.py", line 1474, in raise_routing_exception
    raise request.routing_exception  # type: ignore
  File "/Users/rossroberts/repositories/MediaTracker/env/lib/python3.9/site-packages/flask/ctx.py", line 367, in match_request
    result = self.url_adapter.match(return_rule=True)  # type: ignore
  File "/Users/rossroberts/repositories/MediaTracker/env/lib/python3.9/site-packages/werkzeug/routing.py", line 2041, in match
    raise NotFound()
werkzeug.exceptions.NotFound: 404 Not Found: The requested URL was not found on the server. If you entered the URL manually please check your spelling and try again.

During handling of the above exception, another exception occurred:

Traceback (most recent call last):
  File "/Users/rossroberts/repositories/MediaTracker/env/lib/python3.9/site-packages/sqlalchemy/engine/base.py", line 1802, in _execute_context
    self.dialect.do_execute(
  File "/Users/rossroberts/repositories/MediaTracker/env/lib/python3.9/site-packages/sqlalchemy/engine/default.py", line 732, in do_execute
    cursor.execute(statement, parameters)
sqlite3.OperationalError: no such table: user

The above exception was the direct cause of the following exception:

Traceback (most recent call last):
  File "/Users/rossroberts/repositories/MediaTracker/env/lib/python3.9/site-packages/flask/app.py", line 2073, in wsgi_app
    response = self.full_dispatch_request()
  File "/Users/rossroberts/repositories/MediaTracker/env/lib/python3.9/site-packages/flask/app.py", line 1518, in full_dispatch_request
    rv = self.handle_user_exception(e)
  File "/Users/rossroberts/repositories/MediaTracker/env/lib/python3.9/site-packages/flask/app.py", line 1386, in handle_user_exception
    return self.handle_http_exception(e)
  File "/Users/rossroberts/repositories/MediaTracker/env/lib/python3.9/site-packages/flask/app.py", line 1326, in handle_http_exception
    return self.ensure_sync(handler)(e)
  File "/Users/rossroberts/repositories/MediaTracker/app/errors/handlers.py", line 8, in not_found_error
    return render_template('errors/404.html'), 404
  File "/Users/rossroberts/repositories/MediaTracker/env/lib/python3.9/site-packages/flask/templating.py", line 146, in render_template
    ctx.app.update_template_context(context)
  File "/Users/rossroberts/repositories/MediaTracker/env/lib/python3.9/site-packages/flask/app.py", line 756, in update_template_context
    context.update(func())
  File "/Users/rossroberts/repositories/MediaTracker/env/lib/python3.9/site-packages/flask_login/utils.py", line 379, in _user_context_processor
    return dict(current_user=_get_user())
  File "/Users/rossroberts/repositories/MediaTracker/env/lib/python3.9/site-packages/flask_login/utils.py", line 346, in _get_user
    current_app.login_manager._load_user()
  File "/Users/rossroberts/repositories/MediaTracker/env/lib/python3.9/site-packages/flask_login/login_manager.py", line 318, in _load_user
    user = self._user_callback(user_id)
  File "/Users/rossroberts/repositories/MediaTracker/app/models.py", line 67, in load_user
    return User.query.get(int(id))
  File "<string>", line 2, in get
  File "/Users/rossroberts/repositories/MediaTracker/env/lib/python3.9/site-packages/sqlalchemy/util/deprecations.py", line 401, in warned
    return fn(*args, **kwargs)
  File "/Users/rossroberts/repositories/MediaTracker/env/lib/python3.9/site-packages/sqlalchemy/orm/query.py", line 943, in get
    return self._get_impl(ident, loading.load_on_pk_identity)
  File "/Users/rossroberts/repositories/MediaTracker/env/lib/python3.9/site-packages/sqlalchemy/orm/query.py", line 947, in _get_impl
    return self.session._get_impl(
  File "/Users/rossroberts/repositories/MediaTracker/env/lib/python3.9/site-packages/sqlalchemy/orm/session.py", line 2892, in _get_impl
    return db_load_fn(
  File "/Users/rossroberts/repositories/MediaTracker/env/lib/python3.9/site-packages/sqlalchemy/orm/loading.py", line 530, in load_on_pk_identity
    session.execute(
  File "/Users/rossroberts/repositories/MediaTracker/env/lib/python3.9/site-packages/sqlalchemy/orm/session.py", line 1692, in execute
    result = conn._execute_20(statement, params or {}, execution_options)
  File "/Users/rossroberts/repositories/MediaTracker/env/lib/python3.9/site-packages/sqlalchemy/engine/base.py", line 1614, in _execute_20
    return meth(self, args_10style, kwargs_10style, execution_options)
  File "/Users/rossroberts/repositories/MediaTracker/env/lib/python3.9/site-packages/sqlalchemy/sql/elements.py", line 325, in _execute_on_connection
    return connection._execute_clauseelement(
  File "/Users/rossroberts/repositories/MediaTracker/env/lib/python3.9/site-packages/sqlalchemy/engine/base.py", line 1481, in _execute_clauseelement
    ret = self._execute_context(
  File "/Users/rossroberts/repositories/MediaTracker/env/lib/python3.9/site-packages/sqlalchemy/engine/base.py", line 1845, in _execute_context
    self._handle_dbapi_exception(
  File "/Users/rossroberts/repositories/MediaTracker/env/lib/python3.9/site-packages/sqlalchemy/engine/base.py", line 2026, in _handle_dbapi_exception
    util.raise_(
  File "/Users/rossroberts/repositories/MediaTracker/env/lib/python3.9/site-packages/sqlalchemy/util/compat.py", line 207, in raise_
    raise exception
  File "/Users/rossroberts/repositories/MediaTracker/env/lib/python3.9/site-packages/sqlalchemy/engine/base.py", line 1802, in _execute_context
    self.dialect.do_execute(
  File "/Users/rossroberts/repositories/MediaTracker/env/lib/python3.9/site-packages/sqlalchemy/engine/default.py", line 732, in do_execute
    cursor.execute(statement, parameters)
sqlalchemy.exc.OperationalError: (sqlite3.OperationalError) no such table: user
[SQL: SELECT user.id AS user_id, user.username AS user_username, user.email AS user_email, user.password_hash AS user_password_hash, user.about_me AS user_about_me, user.last_seen AS user_last_seen 
FROM user 
WHERE user.id = ?]
[parameters: (1,)]
(Background on this error at: https://sqlalche.me/e/14/e3q8)
