2022-02-01 08:30:22,318 ERROR: Exception on / [POST] [in /Users/rossroberts/repositories/MediaTracker/env/lib/python3.9/site-packages/flask/app.py:1457]
Traceback (most recent call last):
  File "/Users/rossroberts/repositories/MediaTracker/env/lib/python3.9/site-packages/sqlalchemy/engine/base.py", line 1802, in _execute_context
    self.dialect.do_execute(
  File "/Users/rossroberts/repositories/MediaTracker/env/lib/python3.9/site-packages/sqlalchemy/engine/default.py", line 732, in do_execute
    cursor.execute(statement, parameters)
sqlite3.InterfaceError: Error binding parameter 7 - probably unsupported type.

The above exception was the direct cause of the following exception:

Traceback (most recent call last):
  File "/Users/rossroberts/repositories/MediaTracker/env/lib/python3.9/site-packages/flask/app.py", line 2073, in wsgi_app
    response = self.full_dispatch_request()
  File "/Users/rossroberts/repositories/MediaTracker/env/lib/python3.9/site-packages/flask/app.py", line 1518, in full_dispatch_request
    rv = self.handle_user_exception(e)
  File "/Users/rossroberts/repositories/MediaTracker/env/lib/python3.9/site-packages/flask/app.py", line 1516, in full_dispatch_request
    rv = self.dispatch_request()
  File "/Users/rossroberts/repositories/MediaTracker/env/lib/python3.9/site-packages/flask/app.py", line 1502, in dispatch_request
    return self.ensure_sync(self.view_functions[rule.endpoint])(**req.view_args)
  File "/Users/rossroberts/repositories/MediaTracker/env/lib/python3.9/site-packages/flask_login/utils.py", line 272, in decorated_view
    return func(*args, **kwargs)
  File "/Users/rossroberts/repositories/MediaTracker/app/routes.py", line 29, in index
    db.session.commit()
  File "<string>", line 2, in commit
  File "/Users/rossroberts/repositories/MediaTracker/env/lib/python3.9/site-packages/sqlalchemy/orm/session.py", line 1431, in commit
    self._transaction.commit(_to_root=self.future)
  File "/Users/rossroberts/repositories/MediaTracker/env/lib/python3.9/site-packages/sqlalchemy/orm/session.py", line 829, in commit
    self._prepare_impl()
  File "/Users/rossroberts/repositories/MediaTracker/env/lib/python3.9/site-packages/sqlalchemy/orm/session.py", line 808, in _prepare_impl
    self.session.flush()
  File "/Users/rossroberts/repositories/MediaTracker/env/lib/python3.9/site-packages/sqlalchemy/orm/session.py", line 3363, in flush
    self._flush(objects)
  File "/Users/rossroberts/repositories/MediaTracker/env/lib/python3.9/site-packages/sqlalchemy/orm/session.py", line 3503, in _flush
    transaction.rollback(_capture_exception=True)
  File "/Users/rossroberts/repositories/MediaTracker/env/lib/python3.9/site-packages/sqlalchemy/util/langhelpers.py", line 70, in __exit__
    compat.raise_(
  File "/Users/rossroberts/repositories/MediaTracker/env/lib/python3.9/site-packages/sqlalchemy/util/compat.py", line 207, in raise_
    raise exception
  File "/Users/rossroberts/repositories/MediaTracker/env/lib/python3.9/site-packages/sqlalchemy/orm/session.py", line 3463, in _flush
    flush_context.execute()
  File "/Users/rossroberts/repositories/MediaTracker/env/lib/python3.9/site-packages/sqlalchemy/orm/unitofwork.py", line 456, in execute
    rec.execute(self)
  File "/Users/rossroberts/repositories/MediaTracker/env/lib/python3.9/site-packages/sqlalchemy/orm/unitofwork.py", line 630, in execute
    util.preloaded.orm_persistence.save_obj(
  File "/Users/rossroberts/repositories/MediaTracker/env/lib/python3.9/site-packages/sqlalchemy/orm/persistence.py", line 244, in save_obj
    _emit_insert_statements(
  File "/Users/rossroberts/repositories/MediaTracker/env/lib/python3.9/site-packages/sqlalchemy/orm/persistence.py", line 1221, in _emit_insert_statements
    result = connection._execute_20(
  File "/Users/rossroberts/repositories/MediaTracker/env/lib/python3.9/site-packages/sqlalchemy/engine/base.py", line 1614, in _execute_20
    return meth(self, args_10style, kwargs_10style, execution_options)
  File "/Users/rossroberts/repositories/MediaTracker/env/lib/python3.9/site-packages/sqlalchemy/sql/elements.py", line 325, in _execute_on_connection
    return connection._execute_clauseelement(
  File "/Users/rossroberts/repositories/MediaTracker/env/lib/python3.9/site-packages/sqlalchemy/engine/base.py", line 1481, in _execute_clauseelement
    ret = self._execute_context(
  File "/Users/rossroberts/repositories/MediaTracker/env/lib/python3.9/site-packages/sqlalchemy/engine/base.py", line 1845, in _execute_context
    self._handle_dbapi_exception(
  File "/Users/rossroberts/repositories/MediaTracker/env/lib/python3.9/site-packages/sqlalchemy/engine/base.py", line 2026, in _handle_dbapi_exception
    util.raise_(
  File "/Users/rossroberts/repositories/MediaTracker/env/lib/python3.9/site-packages/sqlalchemy/util/compat.py", line 207, in raise_
    raise exception
  File "/Users/rossroberts/repositories/MediaTracker/env/lib/python3.9/site-packages/sqlalchemy/engine/base.py", line 1802, in _execute_context
    self.dialect.do_execute(
  File "/Users/rossroberts/repositories/MediaTracker/env/lib/python3.9/site-packages/sqlalchemy/engine/default.py", line 732, in do_execute
    cursor.execute(statement, parameters)
sqlalchemy.exc.InterfaceError: (sqlite3.InterfaceError) Error binding parameter 7 - probably unsupported type.
[SQL: INSERT INTO screen (title, genre, year, watched, my_rating, rt_rating, watched_date, tags) VALUES (?, ?, ?, ?, ?, ?, ?, ?)]
[parameters: ('Top Gun', 'Action', 1985, 1, 90, 90, '2022-02-01', {'title': 'Top Gun', 'genre': 'Action', 'year': 1985, 'watched': True, 'my_rating': 90, 'rt_rating': 90, 'watched_date': datetime.date(2022, 2, 1), 'tags': '', 'submit': True, 'csrf_token': 'IjYwZTQ3OGRlZGFlY2VlYjM3NWQwMjdlZjQ4NDk1ODRmNmIxM2FjMGYi.Yfk1zA.3hGUkrEe4eXAWVsnydkRcT9vwGU'})]
(Background on this error at: https://sqlalche.me/e/14/rvf5)
2022-02-01 08:33:06,613 INFO: MediaTracker Startup [in /Users/rossroberts/repositories/MediaTracker/app/__init__.py:47]
2022-02-01 08:34:06,392 ERROR: Exception on /user/rroberts1990 [GET] [in /Users/rossroberts/repositories/MediaTracker/env/lib/python3.9/site-packages/flask/app.py:1457]
Traceback (most recent call last):
  File "/Users/rossroberts/repositories/MediaTracker/env/lib/python3.9/site-packages/flask/app.py", line 2073, in wsgi_app
    response = self.full_dispatch_request()
  File "/Users/rossroberts/repositories/MediaTracker/env/lib/python3.9/site-packages/flask/app.py", line 1518, in full_dispatch_request
    rv = self.handle_user_exception(e)
  File "/Users/rossroberts/repositories/MediaTracker/env/lib/python3.9/site-packages/flask/app.py", line 1516, in full_dispatch_request
    rv = self.dispatch_request()
  File "/Users/rossroberts/repositories/MediaTracker/env/lib/python3.9/site-packages/flask/app.py", line 1502, in dispatch_request
    return self.ensure_sync(self.view_functions[rule.endpoint])(**req.view_args)
  File "/Users/rossroberts/repositories/MediaTracker/env/lib/python3.9/site-packages/flask_login/utils.py", line 272, in decorated_view
    return func(*args, **kwargs)
  File "/Users/rossroberts/repositories/MediaTracker/app/routes.py", line 125, in user
    return render_template('user.html', user=user, posts=posts, form=form)
  File "/Users/rossroberts/repositories/MediaTracker/env/lib/python3.9/site-packages/flask/templating.py", line 148, in render_template
    ctx.app.jinja_env.get_or_select_template(template_name_or_list),
  File "/Users/rossroberts/repositories/MediaTracker/env/lib/python3.9/site-packages/jinja2/environment.py", line 1068, in get_or_select_template
    return self.get_template(template_name_or_list, parent, globals)
  File "/Users/rossroberts/repositories/MediaTracker/env/lib/python3.9/site-packages/jinja2/environment.py", line 997, in get_template
    return self._load_template(name, globals)
  File "/Users/rossroberts/repositories/MediaTracker/env/lib/python3.9/site-packages/jinja2/environment.py", line 958, in _load_template
    template = self.loader.load(self, name, self.make_globals(globals))
  File "/Users/rossroberts/repositories/MediaTracker/env/lib/python3.9/site-packages/jinja2/loaders.py", line 137, in load
    code = environment.compile(source, name, filename)
  File "/Users/rossroberts/repositories/MediaTracker/env/lib/python3.9/site-packages/jinja2/environment.py", line 757, in compile
    self.handle_exception(source=source_hint)
  File "/Users/rossroberts/repositories/MediaTracker/env/lib/python3.9/site-packages/jinja2/environment.py", line 925, in handle_exception
    raise rewrite_traceback_stack(source=source)
  File "/Users/rossroberts/repositories/MediaTracker/app/templates/user.html", line 47, in template
    {{ form.submit(value='Unfollow' }}
jinja2.exceptions.TemplateSyntaxError: unexpected '}', expected ')'
2022-02-01 08:34:40,164 INFO: MediaTracker Startup [in /Users/rossroberts/repositories/MediaTracker/app/__init__.py:47]
